Workbook

Sheet Assumptions & Baseline
A1: RVC Senior-to-Family Homeowner Transition: Financial Model
A2: Assumptions & Baseline Data
A3: Model Date: March 2026 | Updated with MaryBeth Joyce / RVC Tax Calculator data
A5: VILLAGE & HOUSING DEMOGRAPHICS
A6: Parameter | B6: Value | C6: Source | D6: Notes
A7: Total Population | B7: 25770 | C7: Census QuickFacts 2024
A8: Total Housing Units | B8: 10627 | C8: Census QuickFacts 2024
A9: Occupied Housing Units | B9: 10010 | C9: Census QuickFacts 2024
A10: Homeownership Rate | B10: 0.78 | C10: Census QuickFacts 2024
A11: Owner-Occupied Units | B11: =ROUND(B9*B10,0) -> 7808 | C11: Calculated | D11: Calc: B11*B10
A12: Population 65+ | B12: 0.196 | C12: Data USA / ACS 2024 | D12: Health insurance proxy
A13: Median Household Income (All) | B13: 144516 | C13: Census QuickFacts 2023
A14: Median Age | B14: 42.9 | C14: Data USA 2024
A15: Est. Senior (65+) Homeowner Parcels | C15: Calculated | D15: Conservatively ~18% of owner-occ
A16: Est. Senior Homeowner Parcels (count) | B16: =ROUND(B11*0.18,0) -> 1405 | C16: Calculated | D16: Calc: B11*0.18
A18: RVC SCHOOL DISTRICT FINANCIALS (2025-26)
A19: Parameter | B19: Value | C19: Source | D19: Notes
A20: Total Budget | B20: 139890000 | C20: LI Herald / District | D20: $139.89M approved May 2025
A21: Property Tax Levy | B21: 109240000 | C21: LI Herald / District | D21: ~78% of budget
A22: Tax Levy Increase (YoY) | B22: 0.026 | C22: LI Herald | D22: 2.6% for 2025-26
A23: State Aid (Foundation + Expense) | B23: 22000000 | C23: Estimated | D23: ~15.7% of budget
A24: Other Revenue | B24: =B20-B21-B23 -> 8650000 | C24: Calculated | D24: Calc: B20-B21-B23
A25: K-12 Enrollment (2025-26) | B25: 3326 | C25: LI Herald / US News | D25: Declining ~30/yr
A26: Projected Enrollment (2026-27) | B26: 3260 | C26: LI Herald | D26: Down ~50 from 2025-26
A27: Per-Pupil Spending | B27: =ROUND(B20/B25,0) -> 42060 | C27: Calculated | D27: Calc: B20/B25
A28: Out-of-District SpEd Cost | B28: 6380000 | C28: LI Herald | D28: $6.38M projected 2026-27
A29: Allowable Tax Levy (2026-27) | B29: 111911163 | C29: LI Herald | D29: 2.45% increase
A30: Projected Deficit (2026-27) | B30: 3780000 | C30: LI Herald | D30: $3.78M shortfall
A32: RPTL §467 & STAR EXEMPTION PARAMETERS
A33: Parameter | B33: Value | C33: Source | D33: Notes
A34: RVC §467 Max Income for 50% Exemption | B34: 58399 | C34: RVC Tax Office | D34: 2024 income / 2025-26 tax year
A35: §467 Sliding Scale Option Adopted | B35: Yes (Option 3) | C35: Nassau County / RVC | D35: Full sliding scale to 5%
A36: §467 Sliding Scale Max Income | B36: =B34+8400 -> 66799 | C36: Calculated | D36: Calc: B35+8400
A37: Enhanced STAR Income Limit | B37: 110750 | C37: NYS DTF | D37: 2026 threshold
A38: Enhanced STAR Exemption Amount (AV) | B38: 140 | C38: NYS DTF | D38: Class 1, Nassau County
A39: Basic STAR Exemption Amount (AV) | B39: 50 | C39: NYS DTF | D39: Class 1, Nassau County
A40: Enhanced STAR Max School Tax Savings | B40: 2680 | C40: NYS DTF | D40: 2025-26, Class 1
A41: Basic STAR Max School Tax Savings | B41: 1220 | C41: NYS DTF | D41: 2025-26, Class 1
A42: Avg School Tax on Median Home (no exemptions) | B42: 15230 | C42: Estimated | D42: Based on $109M levy / ~7,000 parcels
A43: Avg Enhanced STAR + §467 Combined Savings | B43: 4900 | C43: Estimated | D43: STAR $2,856 + §467 ~$2,600
...

Sheet Scenario Model
A1: Senior-to-Family Homeowner Replacement: Scenario Analysis
A2: Impact on RVC School District Revenue, Enrollment & Per-Pupil Spending
A4: Metric | B4: Baseline (Current) | C4: 10% Replacement | D4: 20% Replacement | E4: 30% Replacement | F4: 40% Replacement | G4: 50% Replacement
A5: HOUSING STOCK TRANSITION
A6: Est. Senior Exempt Parcels | B6: ='Assumptions & Baseline'!B16 -> 1405 | C6: ='Assumptions & Baseline'!B16 -> 1405 | D6: ='Assumptions & Baseline'!B16 -> 1405 | E6: ='Assumptions & Baseline'!B16 -> 1405 | F6: ='Assumptions & Baseline'!B16 -> 1405 | G6: ='Assumptions & Baseline'!B16 -> 1405
A7: Replacement Rate | B7: 0 | C7: 0.1 | D7: 0.2 | E7: 0.3 | F7: 0.4 | G7: 0.5
A8: Parcels Transitioned to Families | B8: =ROUND(B6*B7,0) -> 0 | C8: =ROUND(C6*C7,0) -> 141 | D8: =ROUND(D6*D7,0) -> 281 | E8: =ROUND(E6*E7,0) -> 422 | F8: =ROUND(F6*F7,0) -> 562 | G8: =ROUND(G6*G7,0) -> 703
A9: Remaining Senior Exempt Parcels | B9: =B6-B8 -> 1405 | C9: =C6-C8 -> 1264 | D9: =D6-D8 -> 1124 | E9: =E6-E8 -> 983 | F9: =F6-F8 -> 843 | G9: =G6-G8 -> 702
A10: New Family Parcels (2-child avg) | B10: =B8 -> 0 | C10: =C8 -> 141 | D10: =D8 -> 281 | E10: =E8 -> 422 | F10: =F8 -> 562 | G10: =G8 -> 703
A11: SCHOOL TAX REVENUE IMPACT
A12: Add'l Revenue per Transitioned Parcel | B12: ='Assumptions & Baseline'!B43 -> 4900 | C12: ='Assumptions & Baseline'!B43 -> 4900 | D12: ='Assumptions & Baseline'!B43 -> 4900 | E12: ='Assumptions & Baseline'!B43 -> 4900 | F12: ='Assumptions & Baseline'!B43 -> 4900 | G12: ='Assumptions & Baseline'!B43 -> 4900
A13: Total Additional School Tax Revenue | B13: =B8*B12 -> 0 | C13: =C8*C12 -> 690900 | D13: =D8*D12 -> 1376900 | E13: =E8*E12 -> 2067800 | F13: =F8*F12 -> 2753800 | G13: =G8*G12 -> 3444700
A14: Current School Tax Levy | B14: ='Assumptions & Baseline'!B21 -> 109240000 | C14: ='Assumptions & Baseline'!B21 -> 109240000 | D14: ='Assumptions & Baseline'!B21 -> 109240000 | E14: ='Assumptions & Baseline'!B21 -> 109240000 | F14: ='Assumptions & Baseline'!B21 -> 109240000 | G14: ='Assumptions & Baseline'!B21 -> 109240000
A15: New Effective School Tax Levy | B15: =B14+B13 -> 109240000 | C15: =C14+C13 -> 109930900 | D15: =D14+D13 -> 110616900 | E15: =E14+E13 -> 111307800 | F15: =F14+F13 -> 111993800 | G15: =G14+G13 -> 112684700
A16: Levy Increase (%) | B16: =IF(B14=0,0,B13/B14) -> 0 | C16: =IF(C14=0,0,C13/C14) -> 0.0063246064 | D16: =IF(D14=0,0,D13/D14) -> 0.012604357 | E16: =IF(E14=0,0,E13/E14) -> 0.018928964 | F16: =IF(F14=0,0,F13/F14) -> 0.025208715 | G16: =IF(G14=0,0,G13/G14) -> 0.031533321
A17: 2026-27 Deficit Coverage ($3.78M) | B17: =IF(B13>=3780000,"Fully Covered",IF(B13>0,B13/3780000,"No Coverage")) -> No Coverage | C17: =IF(C13>=3780000,"Fully Covered",IF(C13>0,C13/3780000,"No Coverage")) -> 0.18277778 | D17: =IF(D13>=3780000,"Fully Covered",IF(D13>0,D13/3780000,"No Coverage")) -> 0.36425926 | E17: =IF(E13>=3780000,"Fully Covered",IF(E13>0,E13/3780000,"No Coverage")) -> 0.54703704 | F17: =IF(F13>=3780000,"Fully Covered",IF(F13>0,F13/3780000,"No Coverage")) -> 0.72851852 | G17: =IF(G13>=3780000,"Fully Covered",IF(G13>0,G13/3780000,"No Coverage")) -> 0.9112963
A18: ENROLLMENT & PER-PUPIL IMPACT
A19: Current K-12 Enrollment | B19: ='Assumptions & Baseline'!B25 -> 3326 | C19: ='Assumptions & Baseline'!B25 -> 3326 | D19: ='Assumptions & Baseline'!B25 -> 3326 | E19: ='Assumptions & Baseline'!B25 -> 3326 | F19: ='Assumptions & Baseline'!B25 -> 3326 | G19: ='Assumptions & Baseline'!B25 -> 3326
A20: New Students (2 per family) | B20: =B10*2 -> 0 | C20: =C10*2 -> 282 | D20: =D10*2 -> 562 | E20: =E10*2 -> 844 | F20: =F10*2 -> 1124 | G20: =G10*2 -> 1406
A21: K-12 Enrollment Adj. Factor (70% school-age) | B21: 0.7 | C21: 0.7 | D21: 0.7 | E21: 0.7 | F21: 0.7 | G21: 0.7
A22: Adj. New K-12 Students | B22: =ROUND(B20*B21,0) -> 0 | C22: =ROUND(C20*C21,0) -> 197 | D22: =ROUND(D20*D21,0) -> 393 | E22: =ROUND(E20*E21,0) -> 591 | F22: =ROUND(F20*F21,0) -> 787 | G22: =ROUND(G20*G21,0) -> 984
A23: New Total K-12 Enrollment | B23: =B19+B22 -> 3326 | C23: =C19+C22 -> 3523 | D23: =D19+D22 -> 3719 | E23: =E19+E22 -> 3917 | F23: =F19+F22 -> 4113 | G23: =G19+G22 -> 4310
A24: Enrollment Change (%) | B24: =IF(B19=0,0,B22/B19) -> 0 | C24: =IF(C19=0,0,C22/C19) -> 0.059230307 | D24: =IF(D19=0,0,D22/D19) -> 0.11815995 | E24: =IF(E19=0,0,E22/E19) -> 0.17769092 | F24: =IF(F19=0,0,F22/F19) -> 0.23662057 | G24: =IF(G19=0,0,G22/G19) -> 0.29585087
A25: Current Per-Pupil Spending | B25: ='Assumptions & Baseline'!B27 -> 42060 | C25: ='Assumptions & Baseline'!B27 -> 42060 | D25: ='Assumptions & Baseline'!B27 -> 42060 | E25: ='Assumptions & Baseline'!B27 -> 42060 | F25: ='Assumptions & Baseline'!B27 -> 42060 | G25: ='Assumptions & Baseline'!B27 -> 42060
A26: New Total Budget (Revenue-Adjusted) | B26: ='Assumptions & Baseline'!B20+B13 -> 139890000 | C26: ='Assumptions & Baseline'!B20+C13 -> 140580900 | D26: ='Assumptions & Baseline'!B20+D13 -> 141266900 | E26: ='Assumptions & Baseline'!B20+E13 -> 141957800 | F26: ='Assumptions & Baseline'!B20+F13 -> 142643800 | G26: ='Assumptions & Baseline'!B20+G13 -> 143334700
A27: New Per-Pupil Spending (Rev+Enroll adj) | B27: =IF(B23=0,0,ROUND(B26/B23,0)) -> 42060 | C27: =IF(C23=0,0,ROUND(C26/C23,0)) -> 39904 | D27: =IF(D23=0,0,ROUND(D26/D23,0)) -> 37985 | E27: =IF(E23=0,0,ROUND(E26/E23,0)) -> 36241 | F27: =IF(F23=0,0,ROUND(F26/F23,0)) -> 34681 | G27: =IF(G23=0,0,ROUND(G26/G23,0)) -> 33256
A28: Per-Pupil Change ($) | B28: =B27-B25 -> 0 | C28: =C27-C25 -> -2156 | D28: =D27-D25 -> -4075 | E28: =E27-E25 -> -5819 | F28: =F27-F25 -> -7379 | G28: =G27-G25 -> -8804
A29: Per-Pupil Change (%) | B29: =IF(B25=0,0,B28/B25) -> 0 | C29: =IF(C25=0,0,C28/C25) -> -0.051260105 | D29: =IF(D25=0,0,D28/D25) -> -0.096885402 | E29: =IF(E25=0,0,E28/E25) -> -0.13834998 | F29: =IF(F25=0,0,F28/F25) -> -0.17543985 | G29: =IF(G25=0,0,G28/G25) -> -0.20932002
A30: DOWNSTREAM TAX & SERVICE IMPACTS
A31: Village General Tax: Add'l Revenue (§467 recapture) | B31: =ROUND(B8*1800,0) -> 0 | C31: =ROUND(C8*1800,0) -> 253800 | D31: =ROUND(D8*1800,0) -> 505800 | E31: =ROUND(E8*1800,0) -> 759600 | F31: =ROUND(F8*1800,0) -> 1011600 | G31: =ROUND(G8*1800,0) -> 1265400
A32: Nassau County Tax: Add'l Revenue (§467 recapture) | B32: =ROUND(B8*900,0) -> 0 | C32: =ROUND(C8*900,0) -> 126900 | D32: =ROUND(D8*900,0) -> 252900 | E32: =ROUND(E8*900,0) -> 379800 | F32: =ROUND(F8*900,0) -> 505800 | G32: =ROUND(G8*900,0) -> 632700
A33: Total Tax Revenue Recapture (All Levels) | B33: =B13+B31+B32 -> 0 | C33: =C13+C31+C32 -> 1071600 | D33: =D13+D31+D32 -> 2135600 | E33: =E13+E31+E32 -> 3207200 | F33: =F13+F31+F32 -> 4271200 | G33: =G13+G31+G32 -> 5342800
A34: Est. Household Consumer Spending (annual) | B34: =ROUND(B10*15000,0) -> 0 | C34: =ROUND(C10*15000,0) -> 2115000 | D34: =ROUND(D10*15000,0) -> 4215000 | E34: =ROUND(E10*15000,0) -> 6330000 | F34: =ROUND(F10*15000,0) -> 8430000 | G34: =ROUND(G10*15000,0) -> 10545000
A35: One-Time: NYS Transfer Tax Revenue | B35: =ROUND(B8*700000*0.004,0) -> 0 | C35: =ROUND(C8*700000*0.004,0) -> 394800 | D35: =ROUND(D8*700000*0.004,0) -> 786800 | E35: =ROUND(E8*700000*0.004,0) -> 1181600 | F35: =ROUND(F8*700000*0.004,0) -> 1573600 | G35: =ROUND(G8*700000*0.004,0) -> 1968400
A36: Est. Add'l School Capacity Cost (one-time) | B36: =IF(B22<=288,0,(B22-288)*5000) -> 0 | C36: =IF(C22<=288,0,(C22-288)*5000) -> 0 | D36: =IF(D22<=288,0,(D22-288)*5000) -> 525000 | E36: =IF(E22<=288,0,(E22-288)*5000) -> 1515000 | F36: =IF(F22<=288,0,(F22-288)*5000) -> 2495000 | G36: =IF(G22<=288,0,(G22-288)*5000) -> 3480000
A37: NET FISCAL SUMMARY
A38: Net Annual Revenue Gain (All Tax Levels) | B38: =B33 -> 0 | C38: =C33 -> 1071600 | D38: =D33 -> 2135600 | E38: =E33 -> 3207200 | F38: =F33 -> 4271200 | G38: =G33 -> 5342800
A39: School District: Net Annual Revenue Gain | B39: =B13 -> 0 | C39: =C13 -> 690900 | D39: =D13 -> 1376900 | E39: =E13 -> 2067800 | F39: =F13 -> 2753800 | G39: =G13 -> 3444700
A40: Revenue per New Student Added | B40: =IF(B22=0,0,ROUND(B13/B22,0)) -> 0 | C40: =IF(C22=0,0,ROUND(C13/C22,0)) -> 3507 | D40: =IF(D22=0,0,ROUND(D13/D22,0)) -> 3504 | E40: =IF(E22=0,0,ROUND(E13/E22,0)) -> 3499 | F40: =IF(F22=0,0,ROUND(F13/F22,0)) -> 3499 | G40: =IF(G22=0,0,ROUND(G13/G22,0)) -> 3501
A41: Revenue-to-Marginal-Cost Ratio | B41: =IF(B22=0,0,ROUND(B13/(B22*12000),1)) -> 0 | C41: =IF(C22=0,0,ROUND(C13/(C22*12000),1)) -> 0.3 | D41: =IF(D22=0,0,ROUND(D13/(D22*12000),1)) -> 0.3 | E41: =IF(E22=0,0,ROUND(E13/(E22*12000),1)) -> 0.3 | F41: =IF(F22=0,0,ROUND(F13/(F22*12000),1)) -> 0.3 | G41: =IF(G22=0,0,ROUND(G13/(G22*12000),1)) -> 0.3

Sheet RPTL §467 Deep Dive
A1: RPTL §467 Senior Citizens Exemption: RVC Implementation
A3: RVC §467 SLIDING SCALE (OPTION 3)
A4: Income Range | B4: Exemption % | C4: Est. Assessed Value Reduction | D4: Est. Annual Tax Savings | E4: Notes
A5: ≤ $58,399 | B5: 50% | C5: $362,500 | D5: $7,750 | E5: Maximum exemption
A6: $58,400 - $59,399 | B6: 45% | C6: $326,250 | D6: $6,975 | E6: Option 1 tier
A7: $59,400 - $60,399 | B7: 40% | C7: $290,000 | D7: $6,200 | E7: Option 1 tier
A8: $60,400 - $61,399 | B8: 35% | C8: $253,750 | D8: $5,425 | E8: Option 1 tier
A9: $61,400 - $62,299 | B9: 30% | C9: $217,500 | D9: $4,650 | E9: Option 1 tier
A10: $62,300 - $63,199 | B10: 25% | C10: $181,250 | D10: $3,875 | E10: Option 1 tier
A11: $63,200 - $64,099 | B11: 20% | C11: $145,000 | D11: $3,100 | E11: Option 1 tier
A12: $64,100 - $64,999 | B12: 15% | C12: $108,750 | D12: $2,325 | E12: Option 2 tier
A13: $65,000 - $65,899 | B13: 10% | C13: $72,500 | D13: $1,550 | E13: Option 2 tier
A14: $65,900 - $66,799 | B14: 5% | C14: $36,250 | D14: $775 | E14: Option 3 tier
A15: > $66,799 | B15: 0% | C15: $0 | D15: $0 | E15: No §467 exemption
A18: STAR + §467 COMBINED EFFECT
A19: Scenario | B19: §467 Savings | C19: STAR Savings | D19: Total Savings | E19: Effective Tax Rate
A20: Senior, income ≤$58K, Enhanced STAR | B20: $7,750 | C20: $2,856 | D20: $10,606 | E20: ~32%
A21: Senior, income $62K, Enhanced STAR | B21: $4,650 | C21: $2,856 | D21: $7,506 | E21: ~52%
A22: Senior, income $66K, Enhanced STAR | B22: $775 | C22: $2,856 | D22: $3,631 | E22: ~77%
A23: Senior, income >$110K, Basic STAR only | B23: $0 | C23: $1,068 | D23: $1,068 | E23: ~93%
A24: Non-senior homeowner, Basic STAR | B24: $0 | C24: $1,068 | D24: $1,068 | E24: ~93%
A25: Non-senior homeowner, no STAR (new) | B25: $0 | C25: $0 | D25: $0 | E25: 100%
A28: LEGAL AUTHORITY & GOVERNANCE
A29: Item | B29: Detail | C29: Authority | D29: Notes
A30: State Enabling Statute | B30: RPTL §467 | C30: State legislature | D30: Authorizes but does not mandate
A31: Local Adoption Required | B31: Yes - local law/resolution | C31: Village Board / School Board | D31: Each taxing jurisdiction opts in independently
A32: RVC Village: Adopted? | B32: Yes | C32: Village of RVC | D32: Applies to village general tax
A33: RVC School District: Adopted? | B33: Yes | C33: RVC School Board | D33: Applies to school tax
A34: Town of Hempstead: Adopted? | B34: Yes | C34: Town Board | D34: Applies to town tax
A35: Nassau County: Adopted? | B35: Yes | C35: County Legislature | D35: Applies to county tax
A36: Income Threshold Set By | B36: Each jurisdiction independently | C36: Local discretion | D36: Can differ across overlapping jurisdictions
A37: Sliding Scale Option | B37: Local choice (Options 1-3) | C37: Local discretion | D37: RVC uses Option 3 (full scale)
A38: Annual Renewal Required? | B38: Yes (unless 5-yr waiver adopted) | C38: RPTL §467(7) | D38: Nassau files with county assessor
A39: Can Be Repealed? | B39: Yes - by local law/resolution | C39: Same body that adopted | D39: Requires public hearing

Sheet Sensitivity & Notes
A1: Model Sensitivity Analysis & Key Assumptions
A3: KEY VARIABLE SENSITIVITY
A4: Variable | B4: Low Estimate | C4: Base Case | D4: High Estimate / Notes
A5: Senior exempt parcels (count) | B5: 1,200 | C5: 1,342 | D5: 1,600 (if >65 ownership rate higher)
A6: Avg exemption savings per senior parcel | B6: $3,500 | C6: $5,500 | D6: $7,500 (depends on income distribution)
A7: Children per new family | B7: 1.5 | C7: 2.0 | D7: 2.5
A8: % of children that are K-12 age | B8: 60% | C8: 70% | D8: 80%
A9: Marginal cost per new student | B9: $8,000 | C9: $12,000 | D9: $18,000 (if capacity additions needed)
A10: Village §467 savings per parcel | B10: $1,200 | C10: $1,800 | D10: $2,400
A11: County §467 savings per parcel | B11: $600 | C11: $900 | D11: $1,200
A12: Net local spending per new family | B12: $10,000 | C12: $15,000 | D12: $20,000
A13: Avg home sale price (for transfer tax) | B13: $550,000 | C13: $700,000 | D13: $900,000
A14: Time horizon for full transition | B14: 5 years | C14: 10 years | D14: 20 years (natural attrition only)
A17: MODEL ASSUMPTIONS & LIMITATIONS
A18: 1. Senior exempt parcel count estimated at 18% of owner-occupied units based on 19.6% population 65+ and higher homeownership rates among seniors.
A19: 2. Not all seniors qualify for §467 (income-tested). Model assumes ~75% of senior homeowners receive some level of §467 + Enhanced STAR.
A20: 3. Replacement families assumed to have 2 children; 70% K-12 adjustment accounts for pre-K and post-graduation children.
A21: 4. Marginal cost per student ($12K) assumes existing capacity absorption from 288-student enrollment decline since 2016.
A22: 5. Revenue per transitioned parcel = avg exemption savings that are 'recaptured' when non-exempt owner replaces exempt owner.
A23: 6. Model assumes fixed assessment values; in practice, sales may trigger reassessment in Nassau County's cyclical reassessment system.
A24: 7. STAR credits for new homeowners (post-2015 registrants) are delivered as checks, not exemptions — they reduce state cost, not local levy.
A25: 8. Transition rates (10-50%) are illustrative. Natural attrition (death, relocation to care facilities) drives ~3-5% annual turnover in senior cohort.
A26: 9. Village and county §467 savings estimates are rougher than school tax estimates due to different rate structures.
A27: 10. Consumer spending estimates are net incremental (families with children vs. fixed-income seniors).
A28: 11. This model does not account for potential assessment increases upon sale, which would further increase tax revenue.
A29: 12. One-time transfer tax revenue would be realized in year of sale only; ongoing revenue comes from exemption recapture.
